2018-09-19 17:26:39,768 [Thread-25:7468] [django.request:228] [log:log_response] [WARNING]- Not Found: /favicon.ico
2018-09-19 17:32:12,454 [Thread-2:2608] [django.request:228] [log:log_response] [ERROR]- Internal Server Error: /
Traceback (most recent call last):
  File "C:\Users\lenovo\Anaconda3\envs\django\lib\site-packages\django\core\handlers\exception.py", line 34, in inner
    response = get_response(request)
  File "C:\Users\lenovo\Anaconda3\envs\django\lib\site-packages\django\core\handlers\base.py", line 126, in _get_response
    response = self.process_exception_by_middleware(e, request)
  File "C:\Users\lenovo\Anaconda3\envs\django\lib\site-packages\django\core\handlers\base.py", line 124, in _get_response
    response = wrapped_callback(request, *callback_args, **callback_kwargs)
  File "D:\lilanqing\Project\python\maizixueyuan\django\blog_v1\blog\views.py", line 18, in index
    return render(request, 'index.html', locals())
  File "C:\Users\lenovo\Anaconda3\envs\django\lib\site-packages\django\shortcuts.py", line 36, in render
    content = loader.render_to_string(template_name, context, request, using=using)
  File "C:\Users\lenovo\Anaconda3\envs\django\lib\site-packages\django\template\loader.py", line 62, in render_to_string
    return template.render(context, request)
  File "C:\Users\lenovo\Anaconda3\envs\django\lib\site-packages\django\template\backends\django.py", line 61, in render
    return self.template.render(context)
  File "C:\Users\lenovo\Anaconda3\envs\django\lib\site-packages\django\template\base.py", line 169, in render
    with context.bind_template(self):
  File "C:\Users\lenovo\Anaconda3\envs\django\lib\contextlib.py", line 81, in __enter__
    return next(self.gen)
  File "C:\Users\lenovo\Anaconda3\envs\django\lib\site-packages\django\template\context.py", line 246, in bind_template
    updates.update(processor(self.request))
TypeError: global_setting() takes 0 positional arguments but 1 was given
2018-09-19 18:21:24,444 [Thread-2:9940] [django.request:228] [log:log_response] [WARNING]- Not Found: /favicon.ico
2018-09-20 08:45:23,438 [Thread-3:512] [django.request:228] [log:log_response] [WARNING]- Not Found: /favicon.ico
2018-09-20 08:45:31,892 [Thread-7:4588] [django.request:228] [log:log_response] [WARNING]- Not Found: /favicon.ico
2018-09-20 09:01:32,712 [Thread-3:9616] [django.request:228] [log:log_response] [ERROR]- Internal Server Error: /admin/
Traceback (most recent call last):
  File "C:\Users\lenovo\Anaconda3\envs\django\lib\site-packages\django\contrib\sessions\backends\base.py", line 190, in _get_session
    return self._session_cache
AttributeError: 'SessionStore' object has no attribute '_session_cache'

During handling of the above exception, another exception occurred:

Traceback (most recent call last):
  File "C:\Users\lenovo\Anaconda3\envs\django\lib\site-packages\django\db\backends\utils.py", line 85, in _execute
    return self.cursor.execute(sql, params)
  File "C:\Users\lenovo\Anaconda3\envs\django\lib\site-packages\django\db\backends\mysql\base.py", line 71, in execute
    return self.cursor.execute(query, args)
  File "C:\Users\lenovo\Anaconda3\envs\django\lib\site-packages\MySQLdb\cursors.py", line 250, in execute
    self.errorhandler(self, exc, value)
  File "C:\Users\lenovo\Anaconda3\envs\django\lib\site-packages\MySQLdb\connections.py", line 50, in defaulterrorhandler
    raise errorvalue
  File "C:\Users\lenovo\Anaconda3\envs\django\lib\site-packages\MySQLdb\cursors.py", line 247, in execute
    res = self._query(query)
  File "C:\Users\lenovo\Anaconda3\envs\django\lib\site-packages\MySQLdb\cursors.py", line 412, in _query
    rowcount = self._do_query(q)
  File "C:\Users\lenovo\Anaconda3\envs\django\lib\site-packages\MySQLdb\cursors.py", line 375, in _do_query
    db.query(q)
  File "C:\Users\lenovo\Anaconda3\envs\django\lib\site-packages\MySQLdb\connections.py", line 276, in query
    _mysql.connection.query(self, query)
_mysql_exceptions.ProgrammingError: (1146, "Table 'django.django_session' doesn't exist")

The above exception was the direct cause of the following exception:

Traceback (most recent call last):
  File "C:\Users\lenovo\Anaconda3\envs\django\lib\site-packages\django\core\handlers\exception.py", line 34, in inner
    response = get_response(request)
  File "C:\Users\lenovo\Anaconda3\envs\django\lib\site-packages\django\core\handlers\base.py", line 126, in _get_response
    response = self.process_exception_by_middleware(e, request)
  File "C:\Users\lenovo\Anaconda3\envs\django\lib\site-packages\django\core\handlers\base.py", line 124, in _get_response
    response = wrapped_callback(request, *callback_args, **callback_kwargs)
  File "C:\Users\lenovo\Anaconda3\envs\django\lib\site-packages\django\contrib\admin\sites.py", line 241, in wrapper
    return self.admin_view(view, cacheable)(*args, **kwargs)
  File "C:\Users\lenovo\Anaconda3\envs\django\lib\site-packages\django\utils\decorators.py", line 142, in _wrapped_view
    response = view_func(request, *args, **kwargs)
  File "C:\Users\lenovo\Anaconda3\envs\django\lib\site-packages\django\views\decorators\cache.py", line 44, in _wrapped_view_func
    response = view_func(request, *args, **kwargs)
  File "C:\Users\lenovo\Anaconda3\envs\django\lib\site-packages\django\contrib\admin\sites.py", line 212, in inner
    if not self.has_permission(request):
  File "C:\Users\lenovo\Anaconda3\envs\django\lib\site-packages\django\contrib\admin\sites.py", line 186, in has_permission
    return request.user.is_active and request.user.is_staff
  File "C:\Users\lenovo\Anaconda3\envs\django\lib\site-packages\django\utils\functional.py", line 213, in inner
    self._setup()
  File "C:\Users\lenovo\Anaconda3\envs\django\lib\site-packages\django\utils\functional.py", line 347, in _setup
    self._wrapped = self._setupfunc()
  File "C:\Users\lenovo\Anaconda3\envs\django\lib\site-packages\django\contrib\auth\middleware.py", line 24, in <lambda>
    request.user = SimpleLazyObject(lambda: get_user(request))
  File "C:\Users\lenovo\Anaconda3\envs\django\lib\site-packages\django\contrib\auth\middleware.py", line 12, in get_user
    request._cached_user = auth.get_user(request)
  File "C:\Users\lenovo\Anaconda3\envs\django\lib\site-packages\django\contrib\auth\__init__.py", line 182, in get_user
    user_id = _get_user_session_key(request)
  File "C:\Users\lenovo\Anaconda3\envs\django\lib\site-packages\django\contrib\auth\__init__.py", line 59, in _get_user_session_key
    return get_user_model()._meta.pk.to_python(request.session[SESSION_KEY])
  File "C:\Users\lenovo\Anaconda3\envs\django\lib\site-packages\django\contrib\sessions\backends\base.py", line 55, in __getitem__
    return self._session[key]
  File "C:\Users\lenovo\Anaconda3\envs\django\lib\site-packages\django\contrib\sessions\backends\base.py", line 195, in _get_session
    self._session_cache = self.load()
  File "C:\Users\lenovo\Anaconda3\envs\django\lib\site-packages\django\contrib\sessions\backends\db.py", line 43, in load
    s = self._get_session_from_db()
  File "C:\Users\lenovo\Anaconda3\envs\django\lib\site-packages\django\contrib\sessions\backends\db.py", line 34, in _get_session_from_db
    expire_date__gt=timezone.now()
  File "C:\Users\lenovo\Anaconda3\envs\django\lib\site-packages\django\db\models\manager.py", line 82, in manager_method
    return getattr(self.get_queryset(), name)(*args, **kwargs)
  File "C:\Users\lenovo\Anaconda3\envs\django\lib\site-packages\django\db\models\query.py", line 393, in get
    num = len(clone)
  File "C:\Users\lenovo\Anaconda3\envs\django\lib\site-packages\django\db\models\query.py", line 250, in __len__
    self._fetch_all()
  File "C:\Users\lenovo\Anaconda3\envs\django\lib\site-packages\django\db\models\query.py", line 1186, in _fetch_all
    self._result_cache = list(self._iterable_class(self))
  File "C:\Users\lenovo\Anaconda3\envs\django\lib\site-packages\django\db\models\query.py", line 54, in __iter__
    results = compiler.execute_sql(chunked_fetch=self.chunked_fetch, chunk_size=self.chunk_size)
  File "C:\Users\lenovo\Anaconda3\envs\django\lib\site-packages\django\db\models\sql\compiler.py", line 1065, in execute_sql
    cursor.execute(sql, params)
  File "C:\Users\lenovo\Anaconda3\envs\django\lib\site-packages\django\db\backends\utils.py", line 100, in execute
    return super().execute(sql, params)
  File "C:\Users\lenovo\Anaconda3\envs\django\lib\site-packages\django\db\backends\utils.py", line 68, in execute
    return self._execute_with_wrappers(sql, params, many=False, executor=self._execute)
  File "C:\Users\lenovo\Anaconda3\envs\django\lib\site-packages\django\db\backends\utils.py", line 77, in _execute_with_wrappers
    return executor(sql, params, many, context)
  File "C:\Users\lenovo\Anaconda3\envs\django\lib\site-packages\django\db\backends\utils.py", line 85, in _execute
    return self.cursor.execute(sql, params)
  File "C:\Users\lenovo\Anaconda3\envs\django\lib\site-packages\django\db\utils.py", line 89, in __exit__
    raise dj_exc_value.with_traceback(traceback) from exc_value
  File "C:\Users\lenovo\Anaconda3\envs\django\lib\site-packages\django\db\backends\utils.py", line 85, in _execute
    return self.cursor.execute(sql, params)
  File "C:\Users\lenovo\Anaconda3\envs\django\lib\site-packages\django\db\backends\mysql\base.py", line 71, in execute
    return self.cursor.execute(query, args)
  File "C:\Users\lenovo\Anaconda3\envs\django\lib\site-packages\MySQLdb\cursors.py", line 250, in execute
    self.errorhandler(self, exc, value)
  File "C:\Users\lenovo\Anaconda3\envs\django\lib\site-packages\MySQLdb\connections.py", line 50, in defaulterrorhandler
    raise errorvalue
  File "C:\Users\lenovo\Anaconda3\envs\django\lib\site-packages\MySQLdb\cursors.py", line 247, in execute
    res = self._query(query)
  File "C:\Users\lenovo\Anaconda3\envs\django\lib\site-packages\MySQLdb\cursors.py", line 412, in _query
    rowcount = self._do_query(q)
  File "C:\Users\lenovo\Anaconda3\envs\django\lib\site-packages\MySQLdb\cursors.py", line 375, in _do_query
    db.query(q)
  File "C:\Users\lenovo\Anaconda3\envs\django\lib\site-packages\MySQLdb\connections.py", line 276, in query
    _mysql.connection.query(self, query)
django.db.utils.ProgrammingError: (1146, "Table 'django.django_session' doesn't exist")
2018-09-20 09:07:02,300 [Thread-2:7452] [django.request:228] [log:log_response] [ERROR]- Internal Server Error: /admin/
Traceback (most recent call last):
  File "C:\Users\lenovo\Anaconda3\envs\django\lib\site-packages\django\db\backends\utils.py", line 85, in _execute
    return self.cursor.execute(sql, params)
  File "C:\Users\lenovo\Anaconda3\envs\django\lib\site-packages\django\db\backends\mysql\base.py", line 71, in execute
    return self.cursor.execute(query, args)
  File "C:\Users\lenovo\Anaconda3\envs\django\lib\site-packages\MySQLdb\cursors.py", line 250, in execute
    self.errorhandler(self, exc, value)
  File "C:\Users\lenovo\Anaconda3\envs\django\lib\site-packages\MySQLdb\connections.py", line 50, in defaulterrorhandler
    raise errorvalue
  File "C:\Users\lenovo\Anaconda3\envs\django\lib\site-packages\MySQLdb\cursors.py", line 247, in execute
    res = self._query(query)
  File "C:\Users\lenovo\Anaconda3\envs\django\lib\site-packages\MySQLdb\cursors.py", line 412, in _query
    rowcount = self._do_query(q)
  File "C:\Users\lenovo\Anaconda3\envs\django\lib\site-packages\MySQLdb\cursors.py", line 375, in _do_query
    db.query(q)
  File "C:\Users\lenovo\Anaconda3\envs\django\lib\site-packages\MySQLdb\connections.py", line 276, in query
    _mysql.connection.query(self, query)
_mysql_exceptions.ProgrammingError: (1146, "Table 'django.blog_user' doesn't exist")

The above exception was the direct cause of the following exception:

Traceback (most recent call last):
  File "C:\Users\lenovo\Anaconda3\envs\django\lib\site-packages\django\core\handlers\exception.py", line 34, in inner
    response = get_response(request)
  File "C:\Users\lenovo\Anaconda3\envs\django\lib\site-packages\django\core\handlers\base.py", line 126, in _get_response
    response = self.process_exception_by_middleware(e, request)
  File "C:\Users\lenovo\Anaconda3\envs\django\lib\site-packages\django\core\handlers\base.py", line 124, in _get_response
    response = wrapped_callback(request, *callback_args, **callback_kwargs)
  File "C:\Users\lenovo\Anaconda3\envs\django\lib\site-packages\django\contrib\admin\sites.py", line 241, in wrapper
    return self.admin_view(view, cacheable)(*args, **kwargs)
  File "C:\Users\lenovo\Anaconda3\envs\django\lib\site-packages\django\utils\decorators.py", line 142, in _wrapped_view
    response = view_func(request, *args, **kwargs)
  File "C:\Users\lenovo\Anaconda3\envs\django\lib\site-packages\django\views\decorators\cache.py", line 44, in _wrapped_view_func
    response = view_func(request, *args, **kwargs)
  File "C:\Users\lenovo\Anaconda3\envs\django\lib\site-packages\django\contrib\admin\sites.py", line 212, in inner
    if not self.has_permission(request):
  File "C:\Users\lenovo\Anaconda3\envs\django\lib\site-packages\django\contrib\admin\sites.py", line 186, in has_permission
    return request.user.is_active and request.user.is_staff
  File "C:\Users\lenovo\Anaconda3\envs\django\lib\site-packages\django\utils\functional.py", line 213, in inner
    self._setup()
  File "C:\Users\lenovo\Anaconda3\envs\django\lib\site-packages\django\utils\functional.py", line 347, in _setup
    self._wrapped = self._setupfunc()
  File "C:\Users\lenovo\Anaconda3\envs\django\lib\site-packages\django\contrib\auth\middleware.py", line 24, in <lambda>
    request.user = SimpleLazyObject(lambda: get_user(request))
  File "C:\Users\lenovo\Anaconda3\envs\django\lib\site-packages\django\contrib\auth\middleware.py", line 12, in get_user
    request._cached_user = auth.get_user(request)
  File "C:\Users\lenovo\Anaconda3\envs\django\lib\site-packages\django\contrib\auth\__init__.py", line 189, in get_user
    user = backend.get_user(user_id)
  File "C:\Users\lenovo\Anaconda3\envs\django\lib\site-packages\django\contrib\auth\backends.py", line 98, in get_user
    user = UserModel._default_manager.get(pk=user_id)
  File "C:\Users\lenovo\Anaconda3\envs\django\lib\site-packages\django\db\models\manager.py", line 82, in manager_method
    return getattr(self.get_queryset(), name)(*args, **kwargs)
  File "C:\Users\lenovo\Anaconda3\envs\django\lib\site-packages\django\db\models\query.py", line 393, in get
    num = len(clone)
  File "C:\Users\lenovo\Anaconda3\envs\django\lib\site-packages\django\db\models\query.py", line 250, in __len__
    self._fetch_all()
  File "C:\Users\lenovo\Anaconda3\envs\django\lib\site-packages\django\db\models\query.py", line 1186, in _fetch_all
    self._result_cache = list(self._iterable_class(self))
  File "C:\Users\lenovo\Anaconda3\envs\django\lib\site-packages\django\db\models\query.py", line 54, in __iter__
    results = compiler.execute_sql(chunked_fetch=self.chunked_fetch, chunk_size=self.chunk_size)
  File "C:\Users\lenovo\Anaconda3\envs\django\lib\site-packages\django\db\models\sql\compiler.py", line 1065, in execute_sql
    cursor.execute(sql, params)
  File "C:\Users\lenovo\Anaconda3\envs\django\lib\site-packages\django\db\backends\utils.py", line 100, in execute
    return super().execute(sql, params)
  File "C:\Users\lenovo\Anaconda3\envs\django\lib\site-packages\django\db\backends\utils.py", line 68, in execute
    return self._execute_with_wrappers(sql, params, many=False, executor=self._execute)
  File "C:\Users\lenovo\Anaconda3\envs\django\lib\site-packages\django\db\backends\utils.py", line 77, in _execute_with_wrappers
    return executor(sql, params, many, context)
  File "C:\Users\lenovo\Anaconda3\envs\django\lib\site-packages\django\db\backends\utils.py", line 85, in _execute
    return self.cursor.execute(sql, params)
  File "C:\Users\lenovo\Anaconda3\envs\django\lib\site-packages\django\db\utils.py", line 89, in __exit__
    raise dj_exc_value.with_traceback(traceback) from exc_value
  File "C:\Users\lenovo\Anaconda3\envs\django\lib\site-packages\django\db\backends\utils.py", line 85, in _execute
    return self.cursor.execute(sql, params)
  File "C:\Users\lenovo\Anaconda3\envs\django\lib\site-packages\django\db\backends\mysql\base.py", line 71, in execute
    return self.cursor.execute(query, args)
  File "C:\Users\lenovo\Anaconda3\envs\django\lib\site-packages\MySQLdb\cursors.py", line 250, in execute
    self.errorhandler(self, exc, value)
  File "C:\Users\lenovo\Anaconda3\envs\django\lib\site-packages\MySQLdb\connections.py", line 50, in defaulterrorhandler
    raise errorvalue
  File "C:\Users\lenovo\Anaconda3\envs\django\lib\site-packages\MySQLdb\cursors.py", line 247, in execute
    res = self._query(query)
  File "C:\Users\lenovo\Anaconda3\envs\django\lib\site-packages\MySQLdb\cursors.py", line 412, in _query
    rowcount = self._do_query(q)
  File "C:\Users\lenovo\Anaconda3\envs\django\lib\site-packages\MySQLdb\cursors.py", line 375, in _do_query
    db.query(q)
  File "C:\Users\lenovo\Anaconda3\envs\django\lib\site-packages\MySQLdb\connections.py", line 276, in query
    _mysql.connection.query(self, query)
django.db.utils.ProgrammingError: (1146, "Table 'django.blog_user' doesn't exist")
2018-09-20 09:11:24,677 [Thread-8:6768] [django.request:228] [log:log_response] [ERROR]- Internal Server Error: /admin/
Traceback (most recent call last):
  File "C:\Users\lenovo\Anaconda3\envs\django\lib\site-packages\django\contrib\sessions\backends\base.py", line 190, in _get_session
    return self._session_cache
AttributeError: 'SessionStore' object has no attribute '_session_cache'

During handling of the above exception, another exception occurred:

Traceback (most recent call last):
  File "C:\Users\lenovo\Anaconda3\envs\django\lib\site-packages\django\db\backends\utils.py", line 85, in _execute
    return self.cursor.execute(sql, params)
  File "C:\Users\lenovo\Anaconda3\envs\django\lib\site-packages\django\db\backends\mysql\base.py", line 71, in execute
    return self.cursor.execute(query, args)
  File "C:\Users\lenovo\Anaconda3\envs\django\lib\site-packages\MySQLdb\cursors.py", line 250, in execute
    self.errorhandler(self, exc, value)
  File "C:\Users\lenovo\Anaconda3\envs\django\lib\site-packages\MySQLdb\connections.py", line 50, in defaulterrorhandler
    raise errorvalue
  File "C:\Users\lenovo\Anaconda3\envs\django\lib\site-packages\MySQLdb\cursors.py", line 247, in execute
    res = self._query(query)
  File "C:\Users\lenovo\Anaconda3\envs\django\lib\site-packages\MySQLdb\cursors.py", line 412, in _query
    rowcount = self._do_query(q)
  File "C:\Users\lenovo\Anaconda3\envs\django\lib\site-packages\MySQLdb\cursors.py", line 375, in _do_query
    db.query(q)
  File "C:\Users\lenovo\Anaconda3\envs\django\lib\site-packages\MySQLdb\connections.py", line 276, in query
    _mysql.connection.query(self, query)
_mysql_exceptions.ProgrammingError: (1146, "Table 'django.django_session' doesn't exist")

The above exception was the direct cause of the following exception:

Traceback (most recent call last):
  File "C:\Users\lenovo\Anaconda3\envs\django\lib\site-packages\django\core\handlers\exception.py", line 34, in inner
    response = get_response(request)
  File "C:\Users\lenovo\Anaconda3\envs\django\lib\site-packages\django\core\handlers\base.py", line 126, in _get_response
    response = self.process_exception_by_middleware(e, request)
  File "C:\Users\lenovo\Anaconda3\envs\django\lib\site-packages\django\core\handlers\base.py", line 124, in _get_response
    response = wrapped_callback(request, *callback_args, **callback_kwargs)
  File "C:\Users\lenovo\Anaconda3\envs\django\lib\site-packages\django\contrib\admin\sites.py", line 241, in wrapper
    return self.admin_view(view, cacheable)(*args, **kwargs)
  File "C:\Users\lenovo\Anaconda3\envs\django\lib\site-packages\django\utils\decorators.py", line 142, in _wrapped_view
    response = view_func(request, *args, **kwargs)
  File "C:\Users\lenovo\Anaconda3\envs\django\lib\site-packages\django\views\decorators\cache.py", line 44, in _wrapped_view_func
    response = view_func(request, *args, **kwargs)
  File "C:\Users\lenovo\Anaconda3\envs\django\lib\site-packages\django\contrib\admin\sites.py", line 212, in inner
    if not self.has_permission(request):
  File "C:\Users\lenovo\Anaconda3\envs\django\lib\site-packages\django\contrib\admin\sites.py", line 186, in has_permission
    return request.user.is_active and request.user.is_staff
  File "C:\Users\lenovo\Anaconda3\envs\django\lib\site-packages\django\utils\functional.py", line 213, in inner
    self._setup()
  File "C:\Users\lenovo\Anaconda3\envs\django\lib\site-packages\django\utils\functional.py", line 347, in _setup
    self._wrapped = self._setupfunc()
  File "C:\Users\lenovo\Anaconda3\envs\django\lib\site-packages\django\contrib\auth\middleware.py", line 24, in <lambda>
    request.user = SimpleLazyObject(lambda: get_user(request))
  File "C:\Users\lenovo\Anaconda3\envs\django\lib\site-packages\django\contrib\auth\middleware.py", line 12, in get_user
    request._cached_user = auth.get_user(request)
  File "C:\Users\lenovo\Anaconda3\envs\django\lib\site-packages\django\contrib\auth\__init__.py", line 182, in get_user
    user_id = _get_user_session_key(request)
  File "C:\Users\lenovo\Anaconda3\envs\django\lib\site-packages\django\contrib\auth\__init__.py", line 59, in _get_user_session_key
    return get_user_model()._meta.pk.to_python(request.session[SESSION_KEY])
  File "C:\Users\lenovo\Anaconda3\envs\django\lib\site-packages\django\contrib\sessions\backends\base.py", line 55, in __getitem__
    return self._session[key]
  File "C:\Users\lenovo\Anaconda3\envs\django\lib\site-packages\django\contrib\sessions\backends\base.py", line 195, in _get_session
    self._session_cache = self.load()
  File "C:\Users\lenovo\Anaconda3\envs\django\lib\site-packages\django\contrib\sessions\backends\db.py", line 43, in load
    s = self._get_session_from_db()
  File "C:\Users\lenovo\Anaconda3\envs\django\lib\site-packages\django\contrib\sessions\backends\db.py", line 34, in _get_session_from_db
    expire_date__gt=timezone.now()
  File "C:\Users\lenovo\Anaconda3\envs\django\lib\site-packages\django\db\models\manager.py", line 82, in manager_method
    return getattr(self.get_queryset(), name)(*args, **kwargs)
  File "C:\Users\lenovo\Anaconda3\envs\django\lib\site-packages\django\db\models\query.py", line 393, in get
    num = len(clone)
  File "C:\Users\lenovo\Anaconda3\envs\django\lib\site-packages\django\db\models\query.py", line 250, in __len__
    self._fetch_all()
  File "C:\Users\lenovo\Anaconda3\envs\django\lib\site-packages\django\db\models\query.py", line 1186, in _fetch_all
    self._result_cache = list(self._iterable_class(self))
  File "C:\Users\lenovo\Anaconda3\envs\django\lib\site-packages\django\db\models\query.py", line 54, in __iter__
    results = compiler.execute_sql(chunked_fetch=self.chunked_fetch, chunk_size=self.chunk_size)
  File "C:\Users\lenovo\Anaconda3\envs\django\lib\site-packages\django\db\models\sql\compiler.py", line 1065, in execute_sql
    cursor.execute(sql, params)
  File "C:\Users\lenovo\Anaconda3\envs\django\lib\site-packages\django\db\backends\utils.py", line 100, in execute
    return super().execute(sql, params)
  File "C:\Users\lenovo\Anaconda3\envs\django\lib\site-packages\django\db\backends\utils.py", line 68, in execute
    return self._execute_with_wrappers(sql, params, many=False, executor=self._execute)
  File "C:\Users\lenovo\Anaconda3\envs\django\lib\site-packages\django\db\backends\utils.py", line 77, in _execute_with_wrappers
    return executor(sql, params, many, context)
  File "C:\Users\lenovo\Anaconda3\envs\django\lib\site-packages\django\db\backends\utils.py", line 85, in _execute
    return self.cursor.execute(sql, params)
  File "C:\Users\lenovo\Anaconda3\envs\django\lib\site-packages\django\db\utils.py", line 89, in __exit__
    raise dj_exc_value.with_traceback(traceback) from exc_value
  File "C:\Users\lenovo\Anaconda3\envs\django\lib\site-packages\django\db\backends\utils.py", line 85, in _execute
    return self.cursor.execute(sql, params)
  File "C:\Users\lenovo\Anaconda3\envs\django\lib\site-packages\django\db\backends\mysql\base.py", line 71, in execute
    return self.cursor.execute(query, args)
  File "C:\Users\lenovo\Anaconda3\envs\django\lib\site-packages\MySQLdb\cursors.py", line 250, in execute
    self.errorhandler(self, exc, value)
  File "C:\Users\lenovo\Anaconda3\envs\django\lib\site-packages\MySQLdb\connections.py", line 50, in defaulterrorhandler
    raise errorvalue
  File "C:\Users\lenovo\Anaconda3\envs\django\lib\site-packages\MySQLdb\cursors.py", line 247, in execute
    res = self._query(query)
  File "C:\Users\lenovo\Anaconda3\envs\django\lib\site-packages\MySQLdb\cursors.py", line 412, in _query
    rowcount = self._do_query(q)
  File "C:\Users\lenovo\Anaconda3\envs\django\lib\site-packages\MySQLdb\cursors.py", line 375, in _do_query
    db.query(q)
  File "C:\Users\lenovo\Anaconda3\envs\django\lib\site-packages\MySQLdb\connections.py", line 276, in query
    _mysql.connection.query(self, query)
django.db.utils.ProgrammingError: (1146, "Table 'django.django_session' doesn't exist")
2018-09-20 09:11:29,127 [Thread-9:8364] [django.request:228] [log:log_response] [ERROR]- Internal Server Error: /admin/
Traceback (most recent call last):
  File "C:\Users\lenovo\Anaconda3\envs\django\lib\site-packages\django\contrib\sessions\backends\base.py", line 190, in _get_session
    return self._session_cache
AttributeError: 'SessionStore' object has no attribute '_session_cache'

During handling of the above exception, another exception occurred:

Traceback (most recent call last):
  File "C:\Users\lenovo\Anaconda3\envs\django\lib\site-packages\django\db\backends\utils.py", line 85, in _execute
    return self.cursor.execute(sql, params)
  File "C:\Users\lenovo\Anaconda3\envs\django\lib\site-packages\django\db\backends\mysql\base.py", line 71, in execute
    return self.cursor.execute(query, args)
  File "C:\Users\lenovo\Anaconda3\envs\django\lib\site-packages\MySQLdb\cursors.py", line 250, in execute
    self.errorhandler(self, exc, value)
  File "C:\Users\lenovo\Anaconda3\envs\django\lib\site-packages\MySQLdb\connections.py", line 50, in defaulterrorhandler
    raise errorvalue
  File "C:\Users\lenovo\Anaconda3\envs\django\lib\site-packages\MySQLdb\cursors.py", line 247, in execute
    res = self._query(query)
  File "C:\Users\lenovo\Anaconda3\envs\django\lib\site-packages\MySQLdb\cursors.py", line 412, in _query
    rowcount = self._do_query(q)
  File "C:\Users\lenovo\Anaconda3\envs\django\lib\site-packages\MySQLdb\cursors.py", line 375, in _do_query
    db.query(q)
  File "C:\Users\lenovo\Anaconda3\envs\django\lib\site-packages\MySQLdb\connections.py", line 276, in query
    _mysql.connection.query(self, query)
_mysql_exceptions.ProgrammingError: (1146, "Table 'django.django_session' doesn't exist")

The above exception was the direct cause of the following exception:

Traceback (most recent call last):
  File "C:\Users\lenovo\Anaconda3\envs\django\lib\site-packages\django\core\handlers\exception.py", line 34, in inner
    response = get_response(request)
  File "C:\Users\lenovo\Anaconda3\envs\django\lib\site-packages\django\core\handlers\base.py", line 126, in _get_response
    response = self.process_exception_by_middleware(e, request)
  File "C:\Users\lenovo\Anaconda3\envs\django\lib\site-packages\django\core\handlers\base.py", line 124, in _get_response
    response = wrapped_callback(request, *callback_args, **callback_kwargs)
  File "C:\Users\lenovo\Anaconda3\envs\django\lib\site-packages\django\contrib\admin\sites.py", line 241, in wrapper
    return self.admin_view(view, cacheable)(*args, **kwargs)
  File "C:\Users\lenovo\Anaconda3\envs\django\lib\site-packages\django\utils\decorators.py", line 142, in _wrapped_view
    response = view_func(request, *args, **kwargs)
  File "C:\Users\lenovo\Anaconda3\envs\django\lib\site-packages\django\views\decorators\cache.py", line 44, in _wrapped_view_func
    response = view_func(request, *args, **kwargs)
  File "C:\Users\lenovo\Anaconda3\envs\django\lib\site-packages\django\contrib\admin\sites.py", line 212, in inner
    if not self.has_permission(request):
  File "C:\Users\lenovo\Anaconda3\envs\django\lib\site-packages\django\contrib\admin\sites.py", line 186, in has_permission
    return request.user.is_active and request.user.is_staff
  File "C:\Users\lenovo\Anaconda3\envs\django\lib\site-packages\django\utils\functional.py", line 213, in inner
    self._setup()
  File "C:\Users\lenovo\Anaconda3\envs\django\lib\site-packages\django\utils\functional.py", line 347, in _setup
    self._wrapped = self._setupfunc()
  File "C:\Users\lenovo\Anaconda3\envs\django\lib\site-packages\django\contrib\auth\middleware.py", line 24, in <lambda>
    request.user = SimpleLazyObject(lambda: get_user(request))
  File "C:\Users\lenovo\Anaconda3\envs\django\lib\site-packages\django\contrib\auth\middleware.py", line 12, in get_user
    request._cached_user = auth.get_user(request)
  File "C:\Users\lenovo\Anaconda3\envs\django\lib\site-packages\django\contrib\auth\__init__.py", line 182, in get_user
    user_id = _get_user_session_key(request)
  File "C:\Users\lenovo\Anaconda3\envs\django\lib\site-packages\django\contrib\auth\__init__.py", line 59, in _get_user_session_key
    return get_user_model()._meta.pk.to_python(request.session[SESSION_KEY])
  File "C:\Users\lenovo\Anaconda3\envs\django\lib\site-packages\django\contrib\sessions\backends\base.py", line 55, in __getitem__
    return self._session[key]
  File "C:\Users\lenovo\Anaconda3\envs\django\lib\site-packages\django\contrib\sessions\backends\base.py", line 195, in _get_session
    self._session_cache = self.load()
  File "C:\Users\lenovo\Anaconda3\envs\django\lib\site-packages\django\contrib\sessions\backends\db.py", line 43, in load
    s = self._get_session_from_db()
  File "C:\Users\lenovo\Anaconda3\envs\django\lib\site-packages\django\contrib\sessions\backends\db.py", line 34, in _get_session_from_db
    expire_date__gt=timezone.now()
  File "C:\Users\lenovo\Anaconda3\envs\django\lib\site-packages\django\db\models\manager.py", line 82, in manager_method
    return getattr(self.get_queryset(), name)(*args, **kwargs)
  File "C:\Users\lenovo\Anaconda3\envs\django\lib\site-packages\django\db\models\query.py", line 393, in get
    num = len(clone)
  File "C:\Users\lenovo\Anaconda3\envs\django\lib\site-packages\django\db\models\query.py", line 250, in __len__
    self._fetch_all()
  File "C:\Users\lenovo\Anaconda3\envs\django\lib\site-packages\django\db\models\query.py", line 1186, in _fetch_all
    self._result_cache = list(self._iterable_class(self))
  File "C:\Users\lenovo\Anaconda3\envs\django\lib\site-packages\django\db\models\query.py", line 54, in __iter__
    results = compiler.execute_sql(chunked_fetch=self.chunked_fetch, chunk_size=self.chunk_size)
  File "C:\Users\lenovo\Anaconda3\envs\django\lib\site-packages\django\db\models\sql\compiler.py", line 1065, in execute_sql
    cursor.execute(sql, params)
  File "C:\Users\lenovo\Anaconda3\envs\django\lib\site-packages\django\db\backends\utils.py", line 100, in execute
    return super().execute(sql, params)
  File "C:\Users\lenovo\Anaconda3\envs\django\lib\site-packages\django\db\backends\utils.py", line 68, in execute
    return self._execute_with_wrappers(sql, params, many=False, executor=self._execute)
  File "C:\Users\lenovo\Anaconda3\envs\django\lib\site-packages\django\db\backends\utils.py", line 77, in _execute_with_wrappers
    return executor(sql, params, many, context)
  File "C:\Users\lenovo\Anaconda3\envs\django\lib\site-packages\django\db\backends\utils.py", line 85, in _execute
    return self.cursor.execute(sql, params)
  File "C:\Users\lenovo\Anaconda3\envs\django\lib\site-packages\django\db\utils.py", line 89, in __exit__
    raise dj_exc_value.with_traceback(traceback) from exc_value
  File "C:\Users\lenovo\Anaconda3\envs\django\lib\site-packages\django\db\backends\utils.py", line 85, in _execute
    return self.cursor.execute(sql, params)
  File "C:\Users\lenovo\Anaconda3\envs\django\lib\site-packages\django\db\backends\mysql\base.py", line 71, in execute
    return self.cursor.execute(query, args)
  File "C:\Users\lenovo\Anaconda3\envs\django\lib\site-packages\MySQLdb\cursors.py", line 250, in execute
    self.errorhandler(self, exc, value)
  File "C:\Users\lenovo\Anaconda3\envs\django\lib\site-packages\MySQLdb\connections.py", line 50, in defaulterrorhandler
    raise errorvalue
  File "C:\Users\lenovo\Anaconda3\envs\django\lib\site-packages\MySQLdb\cursors.py", line 247, in execute
    res = self._query(query)
  File "C:\Users\lenovo\Anaconda3\envs\django\lib\site-packages\MySQLdb\cursors.py", line 412, in _query
    rowcount = self._do_query(q)
  File "C:\Users\lenovo\Anaconda3\envs\django\lib\site-packages\MySQLdb\cursors.py", line 375, in _do_query
    db.query(q)
  File "C:\Users\lenovo\Anaconda3\envs\django\lib\site-packages\MySQLdb\connections.py", line 276, in query
    _mysql.connection.query(self, query)
django.db.utils.ProgrammingError: (1146, "Table 'django.django_session' doesn't exist")
