2019-01-23 12:39:20,324 [Thread-20:8004] [django.request:228] [log:log_response] [WARNING]- Not Found: /favicon.ico
2019-01-23 14:40:00,173 [Thread-9:3400] [django.request:228] [log:log_response] [WARNING]- Not Found: /uploads/avatar/default.png
2019-01-23 14:40:33,036 [Thread-18:6232] [django.request:228] [log:log_response] [WARNING]- Not Found: /uploads/avatar/2019/01/6.png
2019-01-23 15:38:08,079 [Thread-2:9156] [django.request:228] [log:log_response] [ERROR]- Internal Server Error: /
Traceback (most recent call last):
  File "C:\Users\lenovo\Anaconda3\envs\django\lib\site-packages\django\core\handlers\exception.py", line 34, in inner
    response = get_response(request)
  File "C:\Users\lenovo\Anaconda3\envs\django\lib\site-packages\django\core\handlers\base.py", line 126, in _get_response
    response = self.process_exception_by_middleware(e, request)
  File "C:\Users\lenovo\Anaconda3\envs\django\lib\site-packages\django\core\handlers\base.py", line 124, in _get_response
    response = wrapped_callback(request, *callback_args, **callback_kwargs)
  File "D:\lilanqing\Project\python\python-project\ziqiangxuetang\myblog\blog\views.py", line 31, in index
    return render(request, 'index.html', locals())
  File "C:\Users\lenovo\Anaconda3\envs\django\lib\site-packages\django\shortcuts.py", line 36, in render
    content = loader.render_to_string(template_name, context, request, using=using)
  File "C:\Users\lenovo\Anaconda3\envs\django\lib\site-packages\django\template\loader.py", line 62, in render_to_string
    return template.render(context, request)
  File "C:\Users\lenovo\Anaconda3\envs\django\lib\site-packages\django\template\backends\django.py", line 61, in render
    return self.template.render(context)
  File "C:\Users\lenovo\Anaconda3\envs\django\lib\site-packages\django\template\base.py", line 169, in render
    with context.bind_template(self):
  File "C:\Users\lenovo\Anaconda3\envs\django\lib\contextlib.py", line 81, in __enter__
    return next(self.gen)
  File "C:\Users\lenovo\Anaconda3\envs\django\lib\site-packages\django\template\context.py", line 246, in bind_template
    updates.update(processor(self.request))
  File "D:\lilanqing\Project\python\python-project\ziqiangxuetang\myblog\blog\views.py", line 17, in global_setting
    archive_list = Article.objects.distinct_date()
AttributeError: 'Manager' object has no attribute 'distinct_date'
2019-01-23 15:38:09,317 [Thread-3:4016] [django.request:228] [log:log_response] [ERROR]- Internal Server Error: /
Traceback (most recent call last):
  File "C:\Users\lenovo\Anaconda3\envs\django\lib\site-packages\django\core\handlers\exception.py", line 34, in inner
    response = get_response(request)
  File "C:\Users\lenovo\Anaconda3\envs\django\lib\site-packages\django\core\handlers\base.py", line 126, in _get_response
    response = self.process_exception_by_middleware(e, request)
  File "C:\Users\lenovo\Anaconda3\envs\django\lib\site-packages\django\core\handlers\base.py", line 124, in _get_response
    response = wrapped_callback(request, *callback_args, **callback_kwargs)
  File "D:\lilanqing\Project\python\python-project\ziqiangxuetang\myblog\blog\views.py", line 31, in index
    return render(request, 'index.html', locals())
  File "C:\Users\lenovo\Anaconda3\envs\django\lib\site-packages\django\shortcuts.py", line 36, in render
    content = loader.render_to_string(template_name, context, request, using=using)
  File "C:\Users\lenovo\Anaconda3\envs\django\lib\site-packages\django\template\loader.py", line 62, in render_to_string
    return template.render(context, request)
  File "C:\Users\lenovo\Anaconda3\envs\django\lib\site-packages\django\template\backends\django.py", line 61, in render
    return self.template.render(context)
  File "C:\Users\lenovo\Anaconda3\envs\django\lib\site-packages\django\template\base.py", line 169, in render
    with context.bind_template(self):
  File "C:\Users\lenovo\Anaconda3\envs\django\lib\contextlib.py", line 81, in __enter__
    return next(self.gen)
  File "C:\Users\lenovo\Anaconda3\envs\django\lib\site-packages\django\template\context.py", line 246, in bind_template
    updates.update(processor(self.request))
  File "D:\lilanqing\Project\python\python-project\ziqiangxuetang\myblog\blog\views.py", line 17, in global_setting
    archive_list = Article.objects.distinct_date()
AttributeError: 'Manager' object has no attribute 'distinct_date'
2019-01-23 15:38:19,849 [Thread-2:9080] [django.request:228] [log:log_response] [ERROR]- Internal Server Error: /
Traceback (most recent call last):
  File "C:\Users\lenovo\Anaconda3\envs\django\lib\site-packages\django\core\handlers\exception.py", line 34, in inner
    response = get_response(request)
  File "C:\Users\lenovo\Anaconda3\envs\django\lib\site-packages\django\core\handlers\base.py", line 126, in _get_response
    response = self.process_exception_by_middleware(e, request)
  File "C:\Users\lenovo\Anaconda3\envs\django\lib\site-packages\django\core\handlers\base.py", line 124, in _get_response
    response = wrapped_callback(request, *callback_args, **callback_kwargs)
  File "D:\lilanqing\Project\python\python-project\ziqiangxuetang\myblog\blog\views.py", line 31, in index
    return render(request, 'index.html', locals())
  File "C:\Users\lenovo\Anaconda3\envs\django\lib\site-packages\django\shortcuts.py", line 36, in render
    content = loader.render_to_string(template_name, context, request, using=using)
  File "C:\Users\lenovo\Anaconda3\envs\django\lib\site-packages\django\template\loader.py", line 62, in render_to_string
    return template.render(context, request)
  File "C:\Users\lenovo\Anaconda3\envs\django\lib\site-packages\django\template\backends\django.py", line 61, in render
    return self.template.render(context)
  File "C:\Users\lenovo\Anaconda3\envs\django\lib\site-packages\django\template\base.py", line 169, in render
    with context.bind_template(self):
  File "C:\Users\lenovo\Anaconda3\envs\django\lib\contextlib.py", line 81, in __enter__
    return next(self.gen)
  File "C:\Users\lenovo\Anaconda3\envs\django\lib\site-packages\django\template\context.py", line 246, in bind_template
    updates.update(processor(self.request))
  File "D:\lilanqing\Project\python\python-project\ziqiangxuetang\myblog\blog\views.py", line 23, in global_setting
    comment_count_list = Comment.objects.values('article').annotate(comment_count=Count('article')).order_by(
NameError: name 'Count' is not defined
2019-01-23 15:38:41,142 [Thread-2:11600] [django.request:228] [log:log_response] [ERROR]- Internal Server Error: /
Traceback (most recent call last):
  File "C:\Users\lenovo\Anaconda3\envs\django\lib\site-packages\django\core\handlers\exception.py", line 34, in inner
    response = get_response(request)
  File "C:\Users\lenovo\Anaconda3\envs\django\lib\site-packages\django\core\handlers\base.py", line 126, in _get_response
    response = self.process_exception_by_middleware(e, request)
  File "C:\Users\lenovo\Anaconda3\envs\django\lib\site-packages\django\core\handlers\base.py", line 124, in _get_response
    response = wrapped_callback(request, *callback_args, **callback_kwargs)
  File "D:\lilanqing\Project\python\python-project\ziqiangxuetang\myblog\blog\views.py", line 31, in index
    return render(request, 'index.html', locals())
  File "C:\Users\lenovo\Anaconda3\envs\django\lib\site-packages\django\shortcuts.py", line 36, in render
    content = loader.render_to_string(template_name, context, request, using=using)
  File "C:\Users\lenovo\Anaconda3\envs\django\lib\site-packages\django\template\loader.py", line 62, in render_to_string
    return template.render(context, request)
  File "C:\Users\lenovo\Anaconda3\envs\django\lib\site-packages\django\template\backends\django.py", line 61, in render
    return self.template.render(context)
  File "C:\Users\lenovo\Anaconda3\envs\django\lib\site-packages\django\template\base.py", line 171, in render
    return self._render(context)
  File "C:\Users\lenovo\Anaconda3\envs\django\lib\site-packages\django\template\base.py", line 163, in _render
    return self.nodelist.render(context)
  File "C:\Users\lenovo\Anaconda3\envs\django\lib\site-packages\django\template\base.py", line 937, in render
    bit = node.render_annotated(context)
  File "C:\Users\lenovo\Anaconda3\envs\django\lib\site-packages\django\template\base.py", line 904, in render_annotated
    return self.render(context)
  File "C:\Users\lenovo\Anaconda3\envs\django\lib\site-packages\django\template\loader_tags.py", line 150, in render
    return compiled_parent._render(context)
  File "C:\Users\lenovo\Anaconda3\envs\django\lib\site-packages\django\template\base.py", line 163, in _render
    return self.nodelist.render(context)
  File "C:\Users\lenovo\Anaconda3\envs\django\lib\site-packages\django\template\base.py", line 937, in render
    bit = node.render_annotated(context)
  File "C:\Users\lenovo\Anaconda3\envs\django\lib\site-packages\django\template\base.py", line 904, in render_annotated
    return self.render(context)
  File "C:\Users\lenovo\Anaconda3\envs\django\lib\site-packages\django\template\defaulttags.py", line 209, in render
    nodelist.append(node.render_annotated(context))
  File "C:\Users\lenovo\Anaconda3\envs\django\lib\site-packages\django\template\base.py", line 904, in render_annotated
    return self.render(context)
  File "C:\Users\lenovo\Anaconda3\envs\django\lib\site-packages\django\template\defaulttags.py", line 442, in render
    url = reverse(view_name, args=args, kwargs=kwargs, current_app=current_app)
  File "C:\Users\lenovo\Anaconda3\envs\django\lib\site-packages\django\urls\base.py", line 90, in reverse
    return iri_to_uri(resolver._reverse_with_prefix(view, prefix, *args, **kwargs))
  File "C:\Users\lenovo\Anaconda3\envs\django\lib\site-packages\django\urls\resolvers.py", line 622, in _reverse_with_prefix
    raise NoReverseMatch(msg)
django.urls.exceptions.NoReverseMatch: Reverse for 'category' not found. 'category' is not a valid view function or pattern name.
2019-01-23 15:39:09,673 [Thread-4:9576] [django.request:228] [log:log_response] [ERROR]- Internal Server Error: /
Traceback (most recent call last):
  File "C:\Users\lenovo\Anaconda3\envs\django\lib\site-packages\django\core\handlers\exception.py", line 34, in inner
    response = get_response(request)
  File "C:\Users\lenovo\Anaconda3\envs\django\lib\site-packages\django\core\handlers\base.py", line 126, in _get_response
    response = self.process_exception_by_middleware(e, request)
  File "C:\Users\lenovo\Anaconda3\envs\django\lib\site-packages\django\core\handlers\base.py", line 124, in _get_response
    response = wrapped_callback(request, *callback_args, **callback_kwargs)
  File "D:\lilanqing\Project\python\python-project\ziqiangxuetang\myblog\blog\views.py", line 31, in index
    return render(request, 'index.html', locals())
  File "C:\Users\lenovo\Anaconda3\envs\django\lib\site-packages\django\shortcuts.py", line 36, in render
    content = loader.render_to_string(template_name, context, request, using=using)
  File "C:\Users\lenovo\Anaconda3\envs\django\lib\site-packages\django\template\loader.py", line 62, in render_to_string
    return template.render(context, request)
  File "C:\Users\lenovo\Anaconda3\envs\django\lib\site-packages\django\template\backends\django.py", line 61, in render
    return self.template.render(context)
  File "C:\Users\lenovo\Anaconda3\envs\django\lib\site-packages\django\template\base.py", line 171, in render
    return self._render(context)
  File "C:\Users\lenovo\Anaconda3\envs\django\lib\site-packages\django\template\base.py", line 163, in _render
    return self.nodelist.render(context)
  File "C:\Users\lenovo\Anaconda3\envs\django\lib\site-packages\django\template\base.py", line 937, in render
    bit = node.render_annotated(context)
  File "C:\Users\lenovo\Anaconda3\envs\django\lib\site-packages\django\template\base.py", line 904, in render_annotated
    return self.render(context)
  File "C:\Users\lenovo\Anaconda3\envs\django\lib\site-packages\django\template\loader_tags.py", line 150, in render
    return compiled_parent._render(context)
  File "C:\Users\lenovo\Anaconda3\envs\django\lib\site-packages\django\template\base.py", line 163, in _render
    return self.nodelist.render(context)
  File "C:\Users\lenovo\Anaconda3\envs\django\lib\site-packages\django\template\base.py", line 937, in render
    bit = node.render_annotated(context)
  File "C:\Users\lenovo\Anaconda3\envs\django\lib\site-packages\django\template\base.py", line 904, in render_annotated
    return self.render(context)
  File "C:\Users\lenovo\Anaconda3\envs\django\lib\site-packages\django\template\defaulttags.py", line 209, in render
    nodelist.append(node.render_annotated(context))
  File "C:\Users\lenovo\Anaconda3\envs\django\lib\site-packages\django\template\base.py", line 904, in render_annotated
    return self.render(context)
  File "C:\Users\lenovo\Anaconda3\envs\django\lib\site-packages\django\template\defaulttags.py", line 442, in render
    url = reverse(view_name, args=args, kwargs=kwargs, current_app=current_app)
  File "C:\Users\lenovo\Anaconda3\envs\django\lib\site-packages\django\urls\base.py", line 90, in reverse
    return iri_to_uri(resolver._reverse_with_prefix(view, prefix, *args, **kwargs))
  File "C:\Users\lenovo\Anaconda3\envs\django\lib\site-packages\django\urls\resolvers.py", line 622, in _reverse_with_prefix
    raise NoReverseMatch(msg)
django.urls.exceptions.NoReverseMatch: Reverse for 'category' not found. 'category' is not a valid view function or pattern name.
2019-01-23 15:44:37,357 [Thread-2:1052] [django.request:228] [log:log_response] [ERROR]- Internal Server Error: /
Traceback (most recent call last):
  File "C:\Users\lenovo\Anaconda3\envs\django\lib\site-packages\django\core\handlers\exception.py", line 34, in inner
    response = get_response(request)
  File "C:\Users\lenovo\Anaconda3\envs\django\lib\site-packages\django\core\handlers\base.py", line 126, in _get_response
    response = self.process_exception_by_middleware(e, request)
  File "C:\Users\lenovo\Anaconda3\envs\django\lib\site-packages\django\core\handlers\base.py", line 124, in _get_response
    response = wrapped_callback(request, *callback_args, **callback_kwargs)
  File "D:\lilanqing\Project\python\python-project\ziqiangxuetang\myblog\blog\views.py", line 56, in index
    return render(request, 'index.html', locals())
  File "C:\Users\lenovo\Anaconda3\envs\django\lib\site-packages\django\shortcuts.py", line 36, in render
    content = loader.render_to_string(template_name, context, request, using=using)
  File "C:\Users\lenovo\Anaconda3\envs\django\lib\site-packages\django\template\loader.py", line 62, in render_to_string
    return template.render(context, request)
  File "C:\Users\lenovo\Anaconda3\envs\django\lib\site-packages\django\template\backends\django.py", line 61, in render
    return self.template.render(context)
  File "C:\Users\lenovo\Anaconda3\envs\django\lib\site-packages\django\template\base.py", line 169, in render
    with context.bind_template(self):
  File "C:\Users\lenovo\Anaconda3\envs\django\lib\contextlib.py", line 81, in __enter__
    return next(self.gen)
  File "C:\Users\lenovo\Anaconda3\envs\django\lib\site-packages\django\template\context.py", line 246, in bind_template
    updates.update(processor(self.request))
  File "D:\lilanqing\Project\python\python-project\ziqiangxuetang\myblog\blog\views.py", line 24, in global_setting
    archive_list = Article.objects.distinct_date()
AttributeError: 'Manager' object has no attribute 'distinct_date'
2019-01-23 15:45:23,062 [Thread-2:12192] [django.request:228] [log:log_response] [ERROR]- Internal Server Error: /
Traceback (most recent call last):
  File "C:\Users\lenovo\Anaconda3\envs\django\lib\site-packages\django\core\handlers\exception.py", line 34, in inner
    response = get_response(request)
  File "C:\Users\lenovo\Anaconda3\envs\django\lib\site-packages\django\core\handlers\base.py", line 126, in _get_response
    response = self.process_exception_by_middleware(e, request)
  File "C:\Users\lenovo\Anaconda3\envs\django\lib\site-packages\django\core\handlers\base.py", line 124, in _get_response
    response = wrapped_callback(request, *callback_args, **callback_kwargs)
  File "D:\lilanqing\Project\python\python-project\ziqiangxuetang\myblog\blog\views.py", line 56, in index
    return render(request, 'index.html', locals())
  File "C:\Users\lenovo\Anaconda3\envs\django\lib\site-packages\django\shortcuts.py", line 36, in render
    content = loader.render_to_string(template_name, context, request, using=using)
  File "C:\Users\lenovo\Anaconda3\envs\django\lib\site-packages\django\template\loader.py", line 62, in render_to_string
    return template.render(context, request)
  File "C:\Users\lenovo\Anaconda3\envs\django\lib\site-packages\django\template\backends\django.py", line 61, in render
    return self.template.render(context)
  File "C:\Users\lenovo\Anaconda3\envs\django\lib\site-packages\django\template\base.py", line 171, in render
    return self._render(context)
  File "C:\Users\lenovo\Anaconda3\envs\django\lib\site-packages\django\template\base.py", line 163, in _render
    return self.nodelist.render(context)
  File "C:\Users\lenovo\Anaconda3\envs\django\lib\site-packages\django\template\base.py", line 937, in render
    bit = node.render_annotated(context)
  File "C:\Users\lenovo\Anaconda3\envs\django\lib\site-packages\django\template\base.py", line 904, in render_annotated
    return self.render(context)
  File "C:\Users\lenovo\Anaconda3\envs\django\lib\site-packages\django\template\loader_tags.py", line 150, in render
    return compiled_parent._render(context)
  File "C:\Users\lenovo\Anaconda3\envs\django\lib\site-packages\django\template\base.py", line 163, in _render
    return self.nodelist.render(context)
  File "C:\Users\lenovo\Anaconda3\envs\django\lib\site-packages\django\template\base.py", line 937, in render
    bit = node.render_annotated(context)
  File "C:\Users\lenovo\Anaconda3\envs\django\lib\site-packages\django\template\base.py", line 904, in render_annotated
    return self.render(context)
  File "C:\Users\lenovo\Anaconda3\envs\django\lib\site-packages\django\template\defaulttags.py", line 209, in render
    nodelist.append(node.render_annotated(context))
  File "C:\Users\lenovo\Anaconda3\envs\django\lib\site-packages\django\template\base.py", line 904, in render_annotated
    return self.render(context)
  File "C:\Users\lenovo\Anaconda3\envs\django\lib\site-packages\django\template\defaulttags.py", line 442, in render
    url = reverse(view_name, args=args, kwargs=kwargs, current_app=current_app)
  File "C:\Users\lenovo\Anaconda3\envs\django\lib\site-packages\django\urls\base.py", line 90, in reverse
    return iri_to_uri(resolver._reverse_with_prefix(view, prefix, *args, **kwargs))
  File "C:\Users\lenovo\Anaconda3\envs\django\lib\site-packages\django\urls\resolvers.py", line 622, in _reverse_with_prefix
    raise NoReverseMatch(msg)
django.urls.exceptions.NoReverseMatch: Reverse for 'category' not found. 'category' is not a valid view function or pattern name.
2019-01-23 15:47:12,927 [Thread-13:9580] [django.request:228] [log:log_response] [ERROR]- Internal Server Error: /article/
Traceback (most recent call last):
  File "C:\Users\lenovo\Anaconda3\envs\django\lib\site-packages\django\template\defaulttags.py", line 1020, in find_library
    return parser.libraries[name]
KeyError: 'myfilter'

During handling of the above exception, another exception occurred:

Traceback (most recent call last):
  File "C:\Users\lenovo\Anaconda3\envs\django\lib\site-packages\django\core\handlers\exception.py", line 34, in inner
    response = get_response(request)
  File "C:\Users\lenovo\Anaconda3\envs\django\lib\site-packages\django\core\handlers\base.py", line 126, in _get_response
    response = self.process_exception_by_middleware(e, request)
  File "C:\Users\lenovo\Anaconda3\envs\django\lib\site-packages\django\core\handlers\base.py", line 124, in _get_response
    response = wrapped_callback(request, *callback_args, **callback_kwargs)
  File "D:\lilanqing\Project\python\python-project\ziqiangxuetang\myblog\blog\views.py", line 119, in article
    return render(request, 'article.html', locals())
  File "C:\Users\lenovo\Anaconda3\envs\django\lib\site-packages\django\shortcuts.py", line 36, in render
    content = loader.render_to_string(template_name, context, request, using=using)
  File "C:\Users\lenovo\Anaconda3\envs\django\lib\site-packages\django\template\loader.py", line 61, in render_to_string
    template = get_template(template_name, using=using)
  File "C:\Users\lenovo\Anaconda3\envs\django\lib\site-packages\django\template\loader.py", line 15, in get_template
    return engine.get_template(template_name)
  File "C:\Users\lenovo\Anaconda3\envs\django\lib\site-packages\django\template\backends\django.py", line 34, in get_template
    return Template(self.engine.get_template(template_name), self)
  File "C:\Users\lenovo\Anaconda3\envs\django\lib\site-packages\django\template\engine.py", line 144, in get_template
    template, origin = self.find_template(template_name)
  File "C:\Users\lenovo\Anaconda3\envs\django\lib\site-packages\django\template\engine.py", line 126, in find_template
    template = loader.get_template(name, skip=skip)
  File "C:\Users\lenovo\Anaconda3\envs\django\lib\site-packages\django\template\loaders\base.py", line 30, in get_template
    contents, origin, origin.template_name, self.engine,
  File "C:\Users\lenovo\Anaconda3\envs\django\lib\site-packages\django\template\base.py", line 156, in __init__
    self.nodelist = self.compile_nodelist()
  File "C:\Users\lenovo\Anaconda3\envs\django\lib\site-packages\django\template\base.py", line 194, in compile_nodelist
    return parser.parse()
  File "C:\Users\lenovo\Anaconda3\envs\django\lib\site-packages\django\template\base.py", line 478, in parse
    raise self.error(token, e)
  File "C:\Users\lenovo\Anaconda3\envs\django\lib\site-packages\django\template\base.py", line 476, in parse
    compiled_result = compile_func(self, token)
  File "C:\Users\lenovo\Anaconda3\envs\django\lib\site-packages\django\template\loader_tags.py", line 266, in do_extends
    nodelist = parser.parse()
  File "C:\Users\lenovo\Anaconda3\envs\django\lib\site-packages\django\template\base.py", line 478, in parse
    raise self.error(token, e)
  File "C:\Users\lenovo\Anaconda3\envs\django\lib\site-packages\django\template\base.py", line 476, in parse
    compiled_result = compile_func(self, token)
  File "C:\Users\lenovo\Anaconda3\envs\django\lib\site-packages\django\template\defaulttags.py", line 1077, in load
    lib = find_library(parser, name)
  File "C:\Users\lenovo\Anaconda3\envs\django\lib\site-packages\django\template\defaulttags.py", line 1024, in find_library
    name, "\n".join(sorted(parser.libraries)),
django.template.exceptions.TemplateSyntaxError: 'myfilter' is not a registered tag library. Must be one of:
admin_list
admin_modify
admin_static
admin_urls
cache
i18n
l10n
log
static
staticfiles
tz
2019-01-23 15:47:16,479 [Thread-14:11384] [django.request:228] [log:log_response] [ERROR]- Internal Server Error: /article/
Traceback (most recent call last):
  File "C:\Users\lenovo\Anaconda3\envs\django\lib\site-packages\django\template\defaulttags.py", line 1020, in find_library
    return parser.libraries[name]
KeyError: 'myfilter'

During handling of the above exception, another exception occurred:

Traceback (most recent call last):
  File "C:\Users\lenovo\Anaconda3\envs\django\lib\site-packages\django\core\handlers\exception.py", line 34, in inner
    response = get_response(request)
  File "C:\Users\lenovo\Anaconda3\envs\django\lib\site-packages\django\core\handlers\base.py", line 126, in _get_response
    response = self.process_exception_by_middleware(e, request)
  File "C:\Users\lenovo\Anaconda3\envs\django\lib\site-packages\django\core\handlers\base.py", line 124, in _get_response
    response = wrapped_callback(request, *callback_args, **callback_kwargs)
  File "D:\lilanqing\Project\python\python-project\ziqiangxuetang\myblog\blog\views.py", line 119, in article
    return render(request, 'article.html', locals())
  File "C:\Users\lenovo\Anaconda3\envs\django\lib\site-packages\django\shortcuts.py", line 36, in render
    content = loader.render_to_string(template_name, context, request, using=using)
  File "C:\Users\lenovo\Anaconda3\envs\django\lib\site-packages\django\template\loader.py", line 61, in render_to_string
    template = get_template(template_name, using=using)
  File "C:\Users\lenovo\Anaconda3\envs\django\lib\site-packages\django\template\loader.py", line 15, in get_template
    return engine.get_template(template_name)
  File "C:\Users\lenovo\Anaconda3\envs\django\lib\site-packages\django\template\backends\django.py", line 34, in get_template
    return Template(self.engine.get_template(template_name), self)
  File "C:\Users\lenovo\Anaconda3\envs\django\lib\site-packages\django\template\engine.py", line 144, in get_template
    template, origin = self.find_template(template_name)
  File "C:\Users\lenovo\Anaconda3\envs\django\lib\site-packages\django\template\engine.py", line 126, in find_template
    template = loader.get_template(name, skip=skip)
  File "C:\Users\lenovo\Anaconda3\envs\django\lib\site-packages\django\template\loaders\base.py", line 30, in get_template
    contents, origin, origin.template_name, self.engine,
  File "C:\Users\lenovo\Anaconda3\envs\django\lib\site-packages\django\template\base.py", line 156, in __init__
    self.nodelist = self.compile_nodelist()
  File "C:\Users\lenovo\Anaconda3\envs\django\lib\site-packages\django\template\base.py", line 194, in compile_nodelist
    return parser.parse()
  File "C:\Users\lenovo\Anaconda3\envs\django\lib\site-packages\django\template\base.py", line 478, in parse
    raise self.error(token, e)
  File "C:\Users\lenovo\Anaconda3\envs\django\lib\site-packages\django\template\base.py", line 476, in parse
    compiled_result = compile_func(self, token)
  File "C:\Users\lenovo\Anaconda3\envs\django\lib\site-packages\django\template\loader_tags.py", line 266, in do_extends
    nodelist = parser.parse()
  File "C:\Users\lenovo\Anaconda3\envs\django\lib\site-packages\django\template\base.py", line 478, in parse
    raise self.error(token, e)
  File "C:\Users\lenovo\Anaconda3\envs\django\lib\site-packages\django\template\base.py", line 476, in parse
    compiled_result = compile_func(self, token)
  File "C:\Users\lenovo\Anaconda3\envs\django\lib\site-packages\django\template\defaulttags.py", line 1077, in load
    lib = find_library(parser, name)
  File "C:\Users\lenovo\Anaconda3\envs\django\lib\site-packages\django\template\defaulttags.py", line 1024, in find_library
    name, "\n".join(sorted(parser.libraries)),
django.template.exceptions.TemplateSyntaxError: 'myfilter' is not a registered tag library. Must be one of:
admin_list
admin_modify
admin_static
admin_urls
cache
i18n
l10n
log
static
staticfiles
tz
2019-01-23 17:07:47,218 [Thread-25:3752] [django.request:228] [log:log_response] [WARNING]- Not Found: /favicon.ico
2019-01-23 17:08:00,611 [Thread-26:12212] [django.request:228] [log:log_response] [WARNING]- Not Found: /favicon.ico
